Workbook
Name Prr: #REF!

Sheet Príjmy a výdavky
B2: DAŇOVÁ EVIDENCIA | G2: =List!G5 | H2: =List!G6 | J2: =List!G7
B3: Príjmy a Výdavky | F3: (§ 6 ods. 11 zákona 595/2003 Z.z.)
C5: Začiatočný stav - Pokladňa | E5: 0 | F5: Konečný stav - Pokladňa | G5: ='Prehľad MaZ'!F19 -> 0 | J5: Priebežná položka - príjem | L5: =SUMIFS(J:J,F:F,"PN - Priebežná položka - príjem") -> 8556.84 | M5: =L5-L6 -> 0
C6: Začiatočný stav - Banka 1 | E6: 1957.76 | F6: Konečný stav - Banka 1 | G6: ='Prehľad MaZ'!F25 -> 611.08 | J6: Priebežná položka - výdaj | L6: =SUMIFS(M:M,F:F,"VN - Priebežná položka - výdaj") -> 8556.84
C7: Začiatočný stav - Banka 2 | E7: 0 | F7: Konečný stav - Banka 2 | G7: ='Prehľad MaZ'!F31 -> 0
C8: 45383 | F8: 45657
H9: PRÍJEM | K9: VÝDAJ
H10: =SUBTOTAL(9,PV[DAŇOVÁ SUMA]) -> 7210 | I10: =SUBTOTAL(9,PV[NEDAŇOVÁ SUMA]) -> 8557 | J10: =SUBTOTAL(9,PV[SPOLU SUMA]) -> 15767 | K10: =SUBTOTAL(9,PV[DAŇOVÁ SUMA.]) -> 8444.84 | L10: =SUBTOTAL(9,PV[NEDAŇOVÁ SUMA.]) -> 14436.84 | M10: =SUBTOTAL(9,PV[SPOLU SUMA.]) -> 22881.68
B11: Dátum | C11: Číslo dokladu | D11: Druh dokladu | E11: Pokladňa / Banka / ID | F11: Popis transakcie | G11: Poznámka | H11: DAŇOVÁ SUMA | I11: NEDAŇOVÁ SUMA | J11: SPOLU SUMA | K11: DAŇOVÁ SUMA. | L11: NEDAŇOVÁ SUMA. | M11: SPOLU SUMA.
B12: 45658 | C12: 1 | D12: Príjem | E12: Banka 1 | F12: PN - Úroky | I12: 0.02 | J12: 0.02
B13: 45661 | C13: =C12+1 -> 2 | D13: Výdaj | E13: Banka 1 | F13: VN - Priebežná položka - výdaj | L13: 612.48 | M13: =K13+L13 -> 612.48
B14: 45661 | C14: =C13+1 -> 3 | D14: Príjem | E14: Banka 2 | F14: PN - Priebežná položka - príjem | I14: 612.48 | J14: =I14+H14 -> 612.48
B15: 45661 | C15: =C14+1 -> 4 | D15: Výdaj | E15: Banka 2 | F15: VN - Osobná spotreba | L15: 450 | M15: =K15+L15 -> 450
B16: 45664 | C16: =C15+1 -> 5 | D16: Príjem | E16: Banka 1 | F16: PD - Nájomné | G16: Február | H16: 580 | J16: =I16+H16 -> 580
B17: 45664 | C17: =C16+1 -> 6 | D17: Príjem | E17: Banka 1 | F17: PZ - Zálohové platby | G17: Február | H17: 70 | J17: =I17+H17 -> 70
B18: 45691 | C18: =C17+1 -> 7 | D18: Výdaj | E18: Banka 2 | F18: VD - Zálohová platba za elektriku | G18: Január | K18: 23.15 | M18: 23.15
B19: 45691 | C19: =C18+1 -> 8 | D19: Výdaj | E19: Banka 2 | F19: VD - Zálohová platba za uživanie bytu | G19: Január | K19: 123.92 | M19: 123.92
B20: 45691 | C20: =C19+1 -> 9 | D20: Výdaj | E20: Banka 2 | F20: VD - Zálohová platba za NP | G20: Január | K20: 15.41 | M20: 15.41
B21: 45689 | C21: =C20+1 -> 10 | D21: Príjem | E21: Banka 1 | F21: PN - Úroky | I21: 0.02 | J21: =I21+H21 -> 0.02
B22: 45691 | C22: =C21+1 -> 11 | D22: Výdaj | E22: Banka 1 | F22: VN - Priebežná položka - výdaj | L22: 612.48 | M22: =K22+L22 -> 612.48
B23: 45691 | C23: =C22+1 -> 12 | D23: Príjem | E23: Banka 2 | F23: PN - Priebežná položka - príjem | I23: 612.48 | J23: =I23+H23 -> 612.48
B24: 45691 | C24: =C23+1 -> 13 | D24: Výdaj | E24: Banka 2 | F24: VD - Zálohová platba za elektriku | G24: Február | K24: 23.15 | M24: 23.15
B25: 45691 | C25: =C24+1 -> 14 | D25: Výdaj | E25: Banka 2 | F25: VD - Zálohová platba za uživanie bytu | G25: Február | K25: 123.92 | M25: 123.92
B26: 45691 | C26: =C25+1 -> 15 | D26: Výdaj | E26: Banka 2 | F26: VD - Zálohová platba za NP | G26: Február | K26: 15.41 | M26: 15.41
B27: 45691 | C27: =C26+1 -> 16 | D27: Výdaj | E27: Banka 2 | F27: VN - Osobná spotreba | L27: 450 | M27: 450
B28: 45693 | C28: =C27+1 -> 17 | D28: Príjem | E28: Banka 1 | F28: PD - Nájomné | G28: Marec | H28: 580 | J28: 580
B29: 45693 | C29: =C28+1 -> 18 | D29: Príjem | E29: Banka 1 | F29: PZ - Zálohové platby | G29: Marec | H29: 70 | J29: 70
B30: 45717 | C30: =C29+1 -> 19 | D30: Príjem | E30: Banka 1 | F30: PN - Úroky | I30: 0.02 | J30: =I30+H30 -> 0.02
B31: 45719 | C31: =C30+1 -> 20 | D31: Výdaj | E31: Banka 1 | F31: VN - Priebežná položka - výdaj | L31: 617.74 | M31: =K31+L31 -> 617.74
B32: 45719 | C32: =C31+1 -> 21 | D32: Príjem | E32: Banka 2 | F32: PN - Priebežná položka - príjem | I32: 617.74 | J32: =I32+H32 -> 617.74
B33: 45719 | C33: =C32+1 -> 22 | D33: Výdaj | E33: Banka 2 | F33: VD - Zálohová platba za elektriku | G33: Marec | K33: 23.15 | M33: 23.15
B34: 45719 | C34: =C33+1 -> 23 | D34: Výdaj | E34: Banka 2 | F34: VD - Zálohová platba za uživanie bytu | G34: Marec | K34: 126.87 | M34: 126.87
B35: 45719 | C35: =C34+1 -> 24 | D35: Výdaj | E35: Banka 2 | F35: VD - Zálohová platba za NP | G35: Marec | K35: 15.72 | M35: 15.72
B36: 45719 | C36: =C35+1 -> 25 | D36: Výdaj | E36: Banka 2 | F36: VN - Osobná spotreba | L36: 450 | M36: 450
B37: 45721 | C37: =C36+1 -> 26 | D37: Príjem | E37: Banka 1 | F37: PD - Nájomné | G37: Apríl | H37: 580 | J37: =I37+H37 -> 580
B38: 45721 | C38: =C37+1 -> 27 | D38: Príjem | E38: Banka 1 | F38: PZ - Zálohové platby | G38: Apríl | H38: 70 | J38: =I38+H38 -> 70
B39: 45729 | C39: 28 | D39: Príjem | E39: Banka 1 | F39: PZ - Vyúčtovanie | G39: 1. splatka | H39: 120 | J39: =I39+H39 -> 120
B40: 45748 | C40: 29 | D40: Príjem | E40: Banka 1 | F40: PN - Úroky | I40: 0.02 | J40: =I40+H40 -> 0.02
B41: 45750 | C41: 30 | D41: Výdaj | E41: Banka 1 | F41: VN - Priebežná položka - výdaj | L41: 956.78 | M41: =K41+L41 -> 956.78
B42: 45750 | C42: =C41+1 -> 31 | D42: Príjem | E42: Banka 2 | F42: PN - Priebežná položka - príjem | I42: 956.78 | J42: =I42+H42 -> 956.78
...

Sheet Pohľadávky a záväzky
B2: DAŇOVÁ EVIDENCIA | G2: =List!G4 | I2: =List!G5 | J2: =List!G6 | L2: =List!G7
B3: Pohľadávky a Záväzky | G3: (§ 6 ods. 11 zákona 595/2003 Z.z.)
C6: 45658 | D6: Začiatočný stav pohľadávok | F6: 0 | J6: 46022 | K6: Konečný stav pohľadávok | N6: ='Prehľad MaZ'!C31 -> 0
C7: 45658 | D7: Začiatočný stav záväzkov | F7: 650 | J7: 46022 | K7: Konečný stav záväzkov | N7: ='Prehľad MaZ'!F39 -> 650
K9: =SUBTOTAL(9,PZ[SUMA pohľ. / záväzku]) -> 731.24 | M9: =SUBTOTAL(9,PZ[Suma inkasa / úhrady]) -> 731.24 | N9: =SUBTOTAL(9,PZ[Nedoplatok pohľ. / záväzku]) -> 0
C10: Dátum evidencie | D10: Variabilný symbol | E10: Druh dokladu | F10: P/Z | G10: Dátum splatnosti | H10: Odberateľ / Dodávateľ | I10: Text | J10: Poznámka | K10: SUMA pohľ. / záväzku | L10: Dátum inkasa / úhrady | M10: Suma inkasa / úhrady | N10: Nedoplatok pohľ. / záväzku
C11: 45720 | D11: 909702302 | E11: Iný záväzok | F11: =IF(OR(PZ[[#This Row],[Druh dokladu]]=List!$D$4,PZ[[#This Row],[Druh dokladu]]=List!$D$6,PZ[[#This Row],[Druh dokladu]]=List!$D$8),"Z","P") -> Z | G11: 45751 | H11: Správca bytového domu | I11: Vyúčtovanie nákladov k bytu | K11: 439.99 | L11: 45750 | M11: 439.99 | N11: =PZ[[#This Row],[SUMA pohľ. / záväzku]]-PZ[[#This Row],[Suma inkasa / úhrady]] -> 0
C12: 45727 | D12: 909702302 | E12: Iný záväzok | F12: Z | G12: 45778 | H12: Správca bytového domu | I12: Predpis mes. zalohy za byt | K12: 153 | L12: 45779 | M12: 153 | N12: =PZ[[#This Row],[SUMA pohľ. / záväzku]]-PZ[[#This Row],[Suma inkasa / úhrady]] -> 0
C13: 45792 | D13: 3125072317 | E13: Iný záväzok | F13: Z | G13: 45797 | H13: Hlavné mesto SR | I13: Daň z nehnutelnosti splatka 1 | K13: 46.09 | L13: 45817 | M13: 46.09 | N13: =PZ[[#This Row],[SUMA pohľ. / záväzku]]-PZ[[#This Row],[Suma inkasa / úhrady]] -> 0
C14: 45792 | D14: 3125072317 | E14: Iný záväzok | F14: Z | G14: 45900 | H14: Hlavné mesto SR | I14: Daň z nehnutelnosti splatka 2 | K14: 46.08 | L14: 45876 | M14: 46.08 | N14: =PZ[[#This Row],[SUMA pohľ. / záväzku]]-PZ[[#This Row],[Suma inkasa / úhrady]] -> 0
C15: 45792 | D15: 3125072317 | E15: Iný záväzok | F15: Z | G15: 45961 | H15: Hlavné mesto SR | I15: Daň z nehnutelnosti splatka 3 | K15: 46.08 | L15: 45933 | M15: 46.08 | N15: =PZ[[#This Row],[SUMA pohľ. / záväzku]]-PZ[[#This Row],[Suma inkasa / úhrady]] -> 0

Sheet Zásoby a majetok
B2: DAŇOVÁ EVIDENCIA | F2: =List!G4 | H2: =List!G5 | I2: =List!G6 | K2: =List!G7
B3: Zásoby a Majetok | F3: (§ 6 ods. 11 zákona 595/2003 Z.z.)
C5: 45658 | D5: Začiatočný stav zásob | F5: 0 | H5: 46022 | I5: Konečný stav zásob | L5: ='Prehľad MaZ'!C25 -> 0
C6: 45658 | D6: Začiatočný stav krátkodobého majetku | F6: 0 | H6: 46022 | I6: Konečný stav krátkodobého majetku | L6: ='Prehľad MaZ'!C19 -> 0
C7: 45658 | D7: Začiatočný stav dlhodobého majetku | F7: 229613 | H7: 46022 | I7: Konečný stav dlhodobého majetku | L7: ='Prehľad MaZ'!C13 -> 225575
L9: =SUBTOTAL(9,PZ_8[Peňažná suma]) -> -4037.9983
C10: Dátum | D10: Doklad | E10: Zásoba alebo majetok | F10: Inventárne číslo | G10: Názov | H10: Poznámka | I10: Počet | J10: Merná jednotka | K10: Cena za jednotku | L10: Peňažná suma
C11: 45771 | D11: 1 | E11: Dlhodobý majetok | F11: 1 | G11: Byt 23, koprivnická 9/G | H11: Technické zhodnotenie | I11: 1 | J11: eur | K11: 1730 | L11: 1730
C12: 46022 | D12: 2 | E12: Odpisy | F12: 1 | G12: Byt 23, koprivnická 9/G | H12: 12 mesiacov | I12: 1 | J12: eur | K12: =(-F7/40/12*4+0.44)+(-(F7+K11)/40/12*8+0.72) -> -5767.9983 | L12: =PZ_8[[#This Row],[Cena za jednotku]]*PZ_8[[#This Row],[Počet]] -> -5767.9983

Sheet Zoznamy
C2: Späť do hárku "PRÍJMY A VÝDAVKY" | L2: Späť do hárku "POHĽADÁVKY A ZÁVäZKY"
C4: Príjem | F4: Výdaj | I4: Závierkový | L4: P | O4: Z
B5: Druh Príjmov | C5: PD - Nájomné | E5: Druh Výdavkov | F5: VD - Zálohová platba za uživanie bytu | H5: Závierkový | I5: VDZ - Odpisy | K5: Odberatelia | L5: Nájomník 1 - Benčo | N5: Dodávatelia | O5: RTVS
C6: PD - Zmluvná pokuta | F6: VD - Zálohová platba za elektriku | O6: SPP
C7: PN - Peňažná kaucia | F7: VD - Zálohová platba za NP | O7: Správca bytového domu
C8: PN - Priebežná položka - príjem | F8: VD - Komunálny odpad | O8: SWAN
C9: PZ - Zálohové platby | F9: VD - Koncesionárske poplatky | O9: Telekom
C10: PN - Úroky | F10: VD - Poistenie nehnuteľnosti | O10: Tepovač
C11: PZ - Vyúčtovanie | F11: VD - Poplatok do fondu opráv | O11: Západoslovenské elektrárne
F12: VD - Poplatok za internet | O12: UNIQA poisťovňa
F13: VD - Poplatok za káblovú televíziu | O13: Hlavné mesto SR
F14: VN - Priebežná položka - výdaj | O14: Nájomník 1 - Benčo
F15: VD - Znalecký posudok
F16: VD - Daň z nehnutelnosti
F17: VN - Osobná spotreba
F18: VD - Vyúčtovanie zálohových platieb
F19: VD - Nákup - zhodnotenie nehnuteľnosti

Sheet Prehľad MaZ
B1: Prehľad Majetku a Záväzkov
B5: MAJETOK | F5: =SUM(F6:F10) -> 226186.08
B6: * Dlhodobý majetok | F6: =C13 -> 225575
B7: * Krátkodobý majetok | F7: =C19 -> 0
B8: * Zásoby | F8: =C25 -> 0
B9: * Pohľadávky | F9: =C31 -> 0
B10: * Finančný majetok | F10: =F13 -> 611.08
B13: DLHODOBÝ MAJETOK | C13: =C17 -> 225575 | E13: FINANČNÝ MAJETOK | F13: =SUM(F14:F16) -> 611.08
B14: Začiatočný stav dlhodobého majetku | C14: ='Zásoby a majetok'!F7 -> 229613 | E14: * Pokladňa | F14: =F19 -> 0
B15: Zmena stavu dlhodobého majetku | C15: =SUMIFS('Zásoby a majetok'!L11:L4988,'Zásoby a majetok'!E11:E4988,"Dlhodobý majetok") -> 1730 | E15: * Banka 1 | F15: =F25 -> 611.08
B16: Odpisy | C16: =SUMIFS('Zásoby a majetok'!L11:L4988,'Zásoby a majetok'!E11:E4988,"Odpisy")+SUMIFS('Zásoby a majetok'!L11:L4988,'Zásoby a majetok'!E11:E4988,"Odpisy, ktoré nemožno uplatniť") -> -5767.9983 | E16: * Banka 2 | F16: =F31 -> 0
B17: Konečný stav dlhodobého majetku | C17: =C14+C15+C16 -> 225575
B19: KRÁTKODOBÝ MAJETOK | C19: =C23 -> 0 | E19: POKLADŇA | F19: =F23 -> 0
B20: Začiatočný stav krátkodobého majetku | C20: ='Zásoby a majetok'!F6 -> 0 | E20: Začiatočný stav hotovosti v pokladni | F20: ='Príjmy a výdavky'!E5 -> 0
B21: Zmena stavu krátkodobého majetku | C21: =SUMIFS('Zásoby a majetok'!L11:L4988,'Zásoby a majetok'!E11:E4988,"Krátkodobý majetok") -> 0 | E21: Príjmy inkasované v hotovosti | F21: =SUMIFS('Príjmy a výdavky'!J12:J4970,'Príjmy a výdavky'!E12:E4970,"Pokladňa",'Príjmy a výdavky'!D12:D4970,"Príjem") -> 0
E22: Výdaje hradené v hotovosti | F22: =SUMIFS('Príjmy a výdavky'!M12:M4970,'Príjmy a výdavky'!E12:E4970,"Pokladňa",'Príjmy a výdavky'!D12:D4970,"Výdaj") -> 0
B23: Konečný stav dlhodobého majetku | C23: =C20+C21-C22 -> 0 | E23: Konečný stav v pokladni | F23: =F20+F21-F22 -> 0
B25: ZÁSOBY | C25: =C29 -> 0 | E25: BANKA 1 (B1) | F25: =F29 -> 611.08
B26: Začiatočný stav zásob | C26: ='Zásoby a majetok'!F5 -> 0 | E26: Začiatočný stav peňazí na účte v B1 | F26: ='Príjmy a výdavky'!E6 -> 1957.76
B27: Prírastok zásob za účtovné obdobie | C27: =SUMIFS('Zásoby a majetok'!L11:L4988,'Zásoby a majetok'!E11:E4988,"Zásoba",'Zásoby a majetok'!L11:L4988,">0") -> 0 | E27: Príjmy inkasované bezhotovostne v B1 | F27: =SUMIFS('Príjmy a výdavky'!J12:J4970,'Príjmy a výdavky'!E12:E4970,"Banka 1",'Príjmy a výdavky'!D12:D4970,"Príjem") -> 7210.16
B28: Úbytok zásob za účtovné obdobie | C28: =SUMIFS('Zásoby a majetok'!L11:L4988,'Zásoby a majetok'!E11:E4988,"Zásoba",'Zásoby a majetok'!L11:L4988,"<0") -> 0 | E28: Výdaje hradené bezhotovostne z B1 | F28: =SUMIFS('Príjmy a výdavky'!M12:M4970,'Príjmy a výdavky'!E12:E4970,"Banka 1",'Príjmy a výdavky'!D12:D4970,"Výdaj") -> 8556.84
B29: Konečný stav zásob | C29: =C26+C27+C28 -> 0 | E29: Konečný stav peňazí na účte v B1 | F29: =F26+F27-F28 -> 611.08
B31: POHĽADÁVKY | C31: =C35 -> 0 | E31: BANKA 2 (B2) | F31: =F35 -> 0
B32: Začiatočný stav pohľadávok | C32: ='Pohľadávky a záväzky'!F6 -> 0 | E32: Začiatočný stav peňazí na účte v B2 | F32: ='Príjmy a výdavky'!E7 -> 0
B33: Suma pohľadávok za účtovné obdobie | C33: =SUMIFS('Pohľadávky a záväzky'!K:K,'Pohľadávky a záväzky'!F:F,"P") -> 0 | E33: Príjmy inkasované bezhotovostne v B2 | F33: =SUMIFS('Príjmy a výdavky'!J12:J4970,'Príjmy a výdavky'!E12:E4970,"Banka 2",'Príjmy a výdavky'!D12:D4970,"Príjem") -> 8556.84
B34: Inkasované pohľadávky | C34: =SUMIFS('Pohľadávky a záväzky'!M:M,'Pohľadávky a záväzky'!F:F,"P") -> 0 | E34: Výdaje hradené bezhotovostne z B2 | F34: =SUMIFS('Príjmy a výdavky'!M12:M4970,'Príjmy a výdavky'!E12:E4970,"Banka 2",'Príjmy a výdavky'!D12:D4970,"Výdaj") -> 8556.84
B35: Konečný stav pohľadávok | C35: =C32+C33-C34 -> 0 | E35: Konečný stav peňazí na účte v B2 | F35: =F32+F33-F34 -> 0
B39: ZÁVÄZKY | F39: =F43 -> 650
B40: Začiatočný stav záväzkov | F40: ='Pohľadávky a záväzky'!F7 -> 650
B41: Suma záväzkov za účtovné obdobie | F41: =SUMIFS('Pohľadávky a záväzky'!K:K,'Pohľadávky a záväzky'!F:F,"Z") -> 731.24
B42: Uhradené záväzky | F42: =SUMIFS('Pohľadávky a záväzky'!M:M,'Pohľadávky a záväzky'!F:F,"Z") -> 731.24
B43: Konečný stav záväzkov | F43: =F40+F41-F42 -> 650

Sheet Prehľad PaV
B1: Prehľad Príjmov a Výdavkov
B5: PRÍJMY
B6: * Daňové | C6: =SUM('Príjmy a výdavky'!H11:H4969) -> 7210 | E6: VÝSLEDOK HOSPODÁRENIA
B7: * Nedaňové | C7: =SUM('Príjmy a výdavky'!I11:I4969) -> 8557
E9: =C6-C11 -> -1234.84
B10: VÝDAVKY
B11: * Daňové | C11: =SUM('Príjmy a výdavky'!K11:K4969) -> 8444.84
B12: * Nedaňové | C12: =SUM('Príjmy a výdavky'!L11:L4969) -> 14436.84
B17: Druh príjmov alebo výdavkov | C17: Daňové príjmy | D17: Nedaňové príjmy | E17: Sum of DAŇOVÁ SUMA. | F17: Sum of NEDAŇOVÁ SUMA.
B18: (blank)
B19: VN - Priebežná položka - výdaj | F19: 8556.84
B20: VN - Osobná spotreba | F20: 4150
B21: VDZ - Odpisy | E21: 5768
B22: VD - Zálohová platba za uživanie bytu | E22: 1572.58
B23: VD - Zálohová platba za NP | E23: 172.3
B24: VD - Zálohová platba za elektriku | E24: 282.65
B25: VD - Vyúčtovanie zálohových platieb | E25: 511.06
B26: VD - Nákup - zhodnotenie nehnuteľnosti | F26: 1730
B27: VD - Daň z nehnutelnosti | E27: 138.25
B28: PZ - Zálohové platby | C28: 1050
B29: PZ - Vyúčtovanie | C29: 360
B30: PN - Úroky | D30: 0.16
B31: PN - Priebežná položka - príjem | D31: 8556.84
B32: PD - Nájomné | C32: 5800
B33: Grand Total | C33: 7210 | D33: 8557 | E33: 8444.84 | F33: 14436.84

Sheet Výpočet ZDzP
B1: Výpočet Základu dane z prenájmu
B5: DAŇOVÉ PRÍJMY | C5: =SUM('Príjmy a výdavky'!H11:H4969) -> 7210 | E5: DAŇOVÉ VÝDAVKY | F5: =SUM('Príjmy a výdavky'!K11:K4969) -> 8444.84
B6: * Oslobodené príjmy | C6: 500
B7: Zdaniteľné príjmy z prenájmu | C7: =IF(C5-C6<0,0,C5-C6) -> 6710 | E7: Upravené daňové výdavky | F7: =IF(C7/C5*F5>C7,C7,C7/C5*F5) -> 6710
B8: Zdaniteľné príjmy z prenájmu podľa § 6 ods. 3 sa zapíšu v daňovom priznaní typu B v VI. Oddiele, Tabuľke č. 1, Riadok č. 11 a 13, Stĺpec 1. | E8: Upravené daňové výdavky z prenájmu podľa § 6 ods. 3 sa zapíšu v daňovom priznaní typu B v VI. Oddiele, Tabuľke č. 1, Riadok č. 11 a 13, Stĺpec 2.
B22: Základ dane z prenájmu | D22: =C7-F7 -> 0

Sheet Rozúčtovanie pre Nájomníka
B1: Zmluva | C1: Komunál | D1: Voda | E1: Teplo | F1: ZSE | G1: Rozúčtovanie/ realita
A2: 45383 | B2: 21 | K2: 2024 | L2: Odpočet | N2: Rozdiel | O2: PREDPÍSANÁ ZÁLOHA (€) | P2: SKUTOČNÝ NÁKLAD (€) | Q2: PREPLATOK / NEDOPLATOK | R2: PREDPÍSANÁ ZÁLOHA - nová(€)
A3: 45413 | B3: 70 | C3: 10 | D3: 15 | E3: 35 | F3: 10 | L3: Poč. Stav (20.04.2024) | M3: Stav k 31.12.2024
A4: 45444 | B4: 70 | C4: 10 | D4: 15 | E4: 35 | F4: 10 | K4: Studená voda | L4: 23 | M4: 96 | N4: =M4-L4 -> 73 | O4: 15 | P4: 205.4418 | Q4: =O4*8-P4 -> -85.4418 | R4: 25
A5: 45474 | B5: 70 | C5: 10 | D5: 15 | E5: 35 | F5: 10 | K5: Teplo | L5: 34842 | M5: 37423 | N5: =M5-L5 -> 2581 | O5: 35 | P5: 538.42 | Q5: =O5*8-P5 -> -258.42 | R5: 60
A6: 45505 | B6: 70 | C6: 10 | D6: 15 | E6: 35 | F6: 10 | K6: OLO - smeti | L6: 3 osoby | M6: 3 osoby | N6: - | O6: 10 | P6: =14.51*7 -> 101.57 | Q6: =O6*8-P6 -> -21.57 | R6: 10
A7: 45536 | B7: 70 | C7: 10 | D7: 15 | E7: 35 | F7: 10 | K7: ELEKTRINA - ZSE | L7: 888 | M7: =L7+101*8 -> 1696 | N7: =M7-L7 -> 808 | O7: 10 | P7: =(M7-L7)*0.0833*1.2+(1.5*1.2*8) -> 95.16768 | Q7: =O7*8-P7 -> -15.16768 | R7: 15
A8: 45566 | B8: 70 | C8: 10 | D8: 15 | E8: 35 | F8: 10 | K8: Spolu za mesiac | O8: =SUM(O4:O7) -> 70 | P8: =P9/8 -> 117.57493 | R8: =SUBTOTAL(109,R3:R7) -> 110
A9: 45597 | B9: 70 | C9: 10 | D9: 15 | E9: 35 | F9: 10 | K9: Spolu za rok 2024 | O9: =SUM(O4:O7)*8+21 -> 581 | P9: =SUM(P4:P7) -> 940.59948
A10: 45627 | B10: 70 | C10: 10 | D10: 15 | E10: 35 | F10: 10 | K10: Nedoplatok | Q10: =P9-O9 -> 359.59948
A11: 45658 | B11: 70 | C11: 10 | D11: 15 | E11: 35 | F11: 10
A12: 45689 | B12: 70 | C12: 10 | D12: 15 | E12: 35 | F12: 10 | K12: Nájomné podľa zmluvy | L12: 580
A13: 45717 | B13: 70 | C13: 10 | D13: 15 | E13: 35 | F13: 15 | K13: Zálohy od 1.4. | L13: 120
A14: 45748 | B14: 120 | C14: 10 | D14: 25 | E14: 60 | F14: 25 | K14: Spolu | L14: 700
A15: 45778 | B15: 120 | C15: 10 | D15: 25 | E15: 60 | F15: 25
A16: 45809 | B16: 120 | C16: 10 | D16: 25 | E16: 60 | F16: 25
A17: 45839
A18: 45870
A19: 45901
A20: 45931
A21: 45962
A22: 45992
A29: 690 eur ostatné byty
A30: 176 - 3 osoby
A31: 150 - 2 osoby

Sheet List
A1: Daňová evidencia
B2: =List!G6&", " -> ,
A3: Dátum | B3: Druh dokladu P/V | C3: Pokladňa / Banka / ID | D3: Druh dokladu P/Z | E3: Dátum splatnosti | F3: Zásoba alebo majetok | G3: Daňovník
B4: Príjem | C4: Pokladňa | D4: Faktúra prijatá | E4: 36526 | F4: Zásoba | G4: =""
B5: Výdaj | C5: Banka 1 | D5: Faktúra odoslaná | E5: 73415 | F5: Krátkodobý majetok | G5: =""
B6: Závierkový | C6: Banka 2 | D6: Iný záväzok | F6: Dlhodobý majetok | G6: =""
C7: Interný doklad | D7: Iná pohľadávka | F7: Odpisy | G7: =""
D8: Úhrada záv. min. obdobia
D9: Inkaso pohľ. min. obdobia
